#!/usr/bin/env python3
"""
Comprehensive validation script for error handling implementation.
Validates all requirements from task 8.
"""

import sys
import inspect
from typing import get_type_hints

def validate_custom_exceptions():
    """Validate that custom exception classes are properly implemented."""
    print("üîç Validating custom exception classes...")
    
    try:
        from services.habit_service import (
            HabitServiceError,
            HabitNotFoundError,
            DuplicateCompletionError,
            InvalidHabitDataError,
            HabitOperationError
        )
        
        # Test base exception
        base_error = HabitServiceError("Test message", "TEST_CODE")
        assert hasattr(base_error, 'message')
        assert hasattr(base_error, 'error_code')
        assert base_error.message == "Test message"
        assert base_error.error_code == "TEST_CODE"
        print("  ‚úì HabitServiceError base class implemented correctly")
        
        # Test HabitNotFoundError
        not_found_error = HabitNotFoundError(123)
        assert hasattr(not_found_error, 'habit_id')
        assert not_found_error.habit_id == 123
        assert not_found_error.error_code == "HABIT_NOT_FOUND"
        assert "123" in not_found_error.message
        assert "verify the habit ID exists" in not_found_error.message
        print("  ‚úì HabitNotFoundError implemented with descriptive messages")
        
        # Test DuplicateCompletionError
        duplicate_error = DuplicateCompletionError("Exercise", "2024-01-01")
        assert hasattr(duplicate_error, 'habit_name')
        assert hasattr(duplicate_error, 'completion_date')
        assert duplicate_error.habit_name == "Exercise"
        assert duplicate_error.completion_date == "2024-01-01"
        assert duplicate_error.error_code == "DUPLICATE_COMPLETION"
        assert "Exercise" in duplicate_error.message
        assert "2024-01-01" in duplicate_error.message
        assert "once per day" in duplicate_error.message
        print("  ‚úì DuplicateCompletionError implemented with descriptive messages")
        
        # Test InvalidHabitDataError
        invalid_data_error = InvalidHabitDataError("habit_id", "0", "Must be positive")
        assert hasattr(invalid_data_error, 'field')
        assert hasattr(invalid_data_error, 'value')
        assert hasattr(invalid_data_error, 'constraint')
        assert invalid_data_error.field == "habit_id"
        assert invalid_data_error.value == "0"
        assert invalid_data_error.constraint == "Must be positive"
        assert invalid_data_error.error_code == "INVALID_HABIT_DATA"
        print("  ‚úì InvalidHabitDataError implemented with detailed field information")
        
        # Test HabitOperationError
        operation_error = HabitOperationError("delete", "Habit is in use")
        assert hasattr(operation_error, 'operation')
        assert hasattr(operation_error, 'reason')
        assert operation_error.operation == "delete"
        assert operation_error.reason == "Habit is in use"
        assert operation_error.error_code == "HABIT_OPERATION_ERROR"
        print("  ‚úì HabitOperationError implemented with operation details")
        
        return True
        
    except Exception as e:
        print(f"  ‚úó Custom exception validation failed: {e}")
        return False

def validate_service_error_handling():
    """Validate that service methods properly raise custom exceptions."""
    print("üîç Validating service error handling...")
    
    try:
        from services.habit_service import (
            HabitService,
            HabitNotFoundError,
            DuplicateCompletionError,
            InvalidHabitDataError
        )
        from repositories.habit_repository import HabitRepository
        from models.habit import CreateHabitRequest, UpdateHabitRequest
        from datetime import date, timedelta
        
        service = HabitService(HabitRepository())
        
        # Test invalid habit ID validation
        try:
            service.get_habit_by_id(0)
            print("  ‚úó Should raise InvalidHabitDataError for ID 0")
            return False
        except InvalidHabitDataError as e:
            assert e.error_code == "INVALID_HABIT_DATA"
            assert "positive integer" in e.message
            print("  ‚úì Invalid habit ID validation works")
        
        # Test negative habit ID validation
        try:
            service.get_habit_by_id(-1)
            print("  ‚úó Should raise InvalidHabitDataError for negative ID")
            return False
        except InvalidHabitDataError:
            print("  ‚úì Negative habit ID validation works")
        
        # Test habit not found
        try:
            service.get_habit_by_id(999)
            print("  ‚úó Should raise HabitNotFoundError for non-existent habit")
            return False
        except HabitNotFoundError as e:
            assert e.habit_id == 999
            assert e.error_code == "HABIT_NOT_FOUND"
            print("  ‚úì Habit not found error handling works")
        
        # Test future date validation
        habit = service.create_habit(CreateHabitRequest(name="Test Habit"))
        future_date = date.today() + timedelta(days=1)
        try:
            service.complete_habit_today(habit.id, future_date)
            print("  ‚úó Should raise InvalidHabitDataError for future date")
            return False
        except InvalidHabitDataError as e:
            assert "future dates" in e.message
            print("  ‚úì Future date validation works")
        
        # Test duplicate completion
        service.complete_habit_today(habit.id)
        try:
            service.complete_habit_today(habit.id)
            print("  ‚úó Should raise DuplicateCompletionError for same day completion")
            return False
        except DuplicateCompletionError as e:
            assert e.habit_name == "Test Habit"
            assert e.error_code == "DUPLICATE_COMPLETION"
            print("  ‚úì Duplicate completion error handling works")
        
        # Test empty update request
        empty_request = UpdateHabitRequest()
        try:
            service.update_habit(habit.id, empty_request)
            print("  ‚úó Should raise InvalidHabitDataError for empty update")
            return False
        except InvalidHabitDataError as e:
            assert "at least one field" in e.message.lower()
            print("  ‚úì Empty update request validation works")
        
        return True
        
    except Exception as e:
        print(f"  ‚úó Service error handling validation failed: {e}")
        return False

def validate_api_error_handlers():
    """Validate that API error handlers are properly configured."""
    print("üîç Validating API error handlers...")
    
    try:
        from main import app
        from services.habit_service import (
            HabitNotFoundError,
            DuplicateCompletionError,
            InvalidHabitDataError,
            HabitOperationError,
            HabitServiceError
        )
        
        # Check that exception handlers are registered
        exception_handlers = app.exception_handlers
        
        # Check for custom exception handlers
        handler_classes = [
            HabitNotFoundError,
            DuplicateCompletionError,
            InvalidHabitDataError,
            HabitOperationError,
            HabitServiceError
        ]
        
        for handler_class in handler_classes:
            if handler_class not in exception_handlers:
                print(f"  ‚úó Missing exception handler for {handler_class.__name__}")
                return False
            print(f"  ‚úì Exception handler registered for {handler_class.__name__}")
        
        return True
        
    except Exception as e:
        print(f"  ‚úó API error handler validation failed: {e}")
        return False

def validate_error_response_models():
    """Validate that error response models are properly defined."""
    print("üîç Validating error response models...")
    
    try:
        from models.habit import (
            ErrorResponse,
            HabitNotFoundErrorResponse,
            DuplicateCompletionErrorResponse,
            InvalidHabitDataErrorResponse
        )
        
        # Test base ErrorResponse
        base_response = ErrorResponse(error="Test error", error_code="TEST_CODE")
        assert base_response.error == "Test error"
        assert base_response.error_code == "TEST_CODE"
        print("  ‚úì Base ErrorResponse model works")
        
        # Test HabitNotFoundErrorResponse
        not_found_response = HabitNotFoundErrorResponse(
            error="Habit not found",
            habit_id=123
        )
        assert not_found_response.error_code == "HABIT_NOT_FOUND"
        assert not_found_response.habit_id == 123
        print("  ‚úì HabitNotFoundErrorResponse model works")
        
        # Test DuplicateCompletionErrorResponse
        duplicate_response = DuplicateCompletionErrorResponse(
            error="Already completed",
            habit_name="Exercise",
            completion_date="2024-01-01"
        )
        assert duplicate_response.error_code == "DUPLICATE_COMPLETION"
        assert duplicate_response.habit_name == "Exercise"
        assert duplicate_response.completion_date == "2024-01-01"
        print("  ‚úì DuplicateCompletionErrorResponse model works")
        
        # Test InvalidHabitDataErrorResponse
        invalid_data_response = InvalidHabitDataErrorResponse(
            error="Invalid data",
            field="habit_id",
            value="0",
            constraint="Must be positive"
        )
        assert invalid_data_response.error_code == "INVALID_HABIT_DATA"
        assert invalid_data_response.field == "habit_id"
        assert invalid_data_response.value == "0"
        assert invalid_data_response.constraint == "Must be positive"
        print("  ‚úì InvalidHabitDataErrorResponse model works")
        
        return True
        
    except Exception as e:
        print(f"  ‚úó Error response model validation failed: {e}")
        return False

def validate_descriptive_error_messages():
    """Validate that error messages are descriptive and helpful."""
    print("üîç Validating descriptive error messages...")
    
    try:
        from services.habit_service import (
            HabitNotFoundError,
            DuplicateCompletionError,
            InvalidHabitDataError,
            HabitOperationError
        )
        
        # Test HabitNotFoundError message quality
        error1 = HabitNotFoundError(123)
        message1 = error1.message
        assert "Habit with ID 123 not found" in message1
        assert "verify the habit ID exists" in message1
        print("  ‚úì HabitNotFoundError has descriptive message")
        
        # Test DuplicateCompletionError message quality
        error2 = DuplicateCompletionError("Exercise", "2024-01-01")
        message2 = error2.message
        assert "Exercise" in message2
        assert "2024-01-01" in message2
        assert "already completed" in message2
        assert "once per day" in message2
        print("  ‚úì DuplicateCompletionError has descriptive message")
        
        # Test InvalidHabitDataError message quality
        error3 = InvalidHabitDataError("habit_id", "0", "Must be a positive integer")
        message3 = error3.message
        assert "habit_id" in message3
        assert "0" in message3
        assert "Must be a positive integer" in message3
        print("  ‚úì InvalidHabitDataError has descriptive message")
        
        # Test HabitOperationError message quality
        error4 = HabitOperationError("delete habit", "habit is currently in use")
        message4 = error4.message
        assert "Cannot delete habit" in message4
        assert "habit is currently in use" in message4
        print("  ‚úì HabitOperationError has descriptive message")
        
        return True
        
    except Exception as e:
        print(f"  ‚úó Descriptive error message validation failed: {e}")
        return False

def validate_http_status_mapping():
    """Validate that HTTP status codes are properly mapped."""
    print("üîç Validating HTTP status code mapping...")
    
    try:
        from main import (
            habit_not_found_handler,
            duplicate_completion_handler,
            invalid_habit_data_handler,
            habit_operation_handler,
            habit_service_error_handler
        )
        from services.habit_service import (
            HabitNotFoundError,
            DuplicateCompletionError,
            InvalidHabitDataError,
            HabitOperationError,
            HabitServiceError
        )
        
        # Note: We can't easily test the actual HTTP responses without running the server,
        # but we can verify the handlers exist and are properly structured
        
        handlers = [
            (habit_not_found_handler, "404 for HabitNotFoundError"),
            (duplicate_completion_handler, "409 for DuplicateCompletionError"),
            (invalid_habit_data_handler, "400 for InvalidHabitDataError"),
            (habit_operation_handler, "400 for HabitOperationError"),
            (habit_service_error_handler, "500 for HabitServiceError")
        ]
        
        for handler, description in handlers:
            assert callable(handler), f"Handler {handler.__name__} is not callable"
            print(f"  ‚úì {description} handler exists and is callable")
        
        return True
        
    except Exception as e:
        print(f"  ‚úó HTTP status mapping validation failed: {e}")
        return False

def main():
    """Run all validation tests."""
    print("üöÄ Validating comprehensive error handling implementation")
    print("=" * 60)
    
    validations = [
        ("Custom Exception Classes", validate_custom_exceptions),
        ("Service Error Handling", validate_service_error_handling),
        ("API Error Handlers", validate_api_error_handlers),
        ("Error Response Models", validate_error_response_models),
        ("Descriptive Error Messages", validate_descriptive_error_messages),
        ("HTTP Status Code Mapping", validate_http_status_mapping)
    ]
    
    passed = 0
    total = len(validations)
    
    for name, validation_func in validations:
        print(f"\nüìã {name}")
        print("-" * 40)
        
        try:
            if validation_func():
                passed += 1
                print(f"‚úÖ {name}: PASSED")
            else:
                print(f"‚ùå {name}: FAILED")
        except Exception as e:
            print(f"‚ùå {name}: ERROR - {e}")
    
    print("\n" + "=" * 60)
    print(f"üìä VALIDATION RESULTS: {passed}/{total} validations passed")
    
    if passed == total:
        print("üéâ All error handling requirements are properly implemented!")
        print("\n‚úÖ Task 8 requirements satisfied:")
        print("  ‚Ä¢ Custom exception classes for business logic errors")
        print("  ‚Ä¢ Proper HTTP status code mapping for different error types")
        print("  ‚Ä¢ Descriptive error messages for all validation errors")
        print("  ‚Ä¢ Comprehensive error handling throughout the application")
        return True
    else:
        print("‚ö†Ô∏è  Some error handling requirements need attention")
        return False

if __name__ == "__main__":
    success = main()
    sys.exit(0 if success else 1)